<mujoco model="simple_pendulum">
  <compiler angle="radian"/>
  
  <option gravity="0 0 -9.8" timestep="0.01"/>
  
  <worldbody>
    <light name="light1" pos="0.3 0.3 1"/>
    <geom name="ground" type="plane" pos=" 0 0 -1.2" size="2 2 0.1" rgba="0.5 0.5 0.5 1"/>
    
    <body name="pendulum" pos="0 0 0">
      <joint name="pivot" type="hinge" pos="0 0 0" axis="0 1 0" damping="0.1"/>
      <geom name="rod" type="capsule" fromto="0 0 0 0 0 0.6" size="0.05" rgba="0.5 0.5 0.5 1"/>
      <geom name="mass" type="sphere" pos="0 0 0.6" size="0.07" rgba="0.8 0.2 0.2 1"/>
    </body>
  </worldbody>
  
  <actuator>
    <motor name="torque" joint="pivot" gear="1" ctrllimited="true" ctrlrange="-5 5"/>
  </actuator>
</mujoco>
